Workbook

Sheet DATA SHEET
A7: PROFIT & LOSS
A8: Report Date | B8: 42460 | C8: 42825 | D8: 43190 | E8: 43555 | F8: 43921 | G8: 44286 | H8: 44651 | I8: 45016 | J8: 45382 | K8: 45747
A9: Sales | B9: 273045.6 | C9: 269692.51 | D9: 291550.48 | E9: 301938.4 | F9: 261067.97 | G9: 249794.75 | H9: 278453.62 | I9: 345966.97 | J9: 434016 | K9: 439695
A10: Raw Material Cost | B10: 166134.01 | C10: 173294.08 | D10: 187896.58 | E10: 194267.91 | F10: 164899.82 | G10: 153607.36 | H10: 179295.33 | I10: 231251.26 | J10: 274321 | K10: 268950
A11: Change in Inventory | B11: 2750.99 | C11: 7399.92 | D11: 2046.58 | E11: -2053.28 | F11: -2231.19 | G11: -4684.16 | H11: -1590.49 | I11: 4781.62 | J11: 1566 | K11: -2836
A12: Power and Fuel | B12: 1143.63 | C12: 1159.82 | D12: 1308.08 | E12: 1585.93 | F12: 1264.95 | G12: 1112.87 | H12: 2178.29 | I12: 2513.33 | J12: 2189 | K12: 2443
A13: Other Mfr. Exp | B13: 12101.53 | C13: 10067.37 | D13: 10971.66 | E13: 11694.54 | F13: 11541.51 | G13: 8273.17 | H13: 9427.38 | I13: 11765.97 | J13: 17446 | K13: 18813
A14: Employee Cost | B14: 28880.89 | C14: 28332.89 | D14: 30300.09 | E14: 33243.87 | F14: 30438.6 | G14: 27648.48 | H14: 30808.52 | I14: 33654.7 | J14: 41990 | K14: 47767
A15: Selling and admin | B15: 21991.9 | C15: 30039.38 | D15: 31004.58 | E15: 32719.8 | F15: 29248.32 | G15: 23015.79 | H15: 29205.4 | I15: 34839.19 | J15: 42765 | K15: 47099
A16: Other Expenses | B16: 7149.38 | C16: 4610.2 | D16: 658.39 | E16: 1708.74 | F16: 3456.51 | G16: -834.51 | H16: 1228.12 | I16: 4908.34 | J16: -953 | K16: -3429
A17: Other Income | B17: -2669.62 | C17: 1869.1 | D17: 5932.73 | E17: -26686.25 | F17: 101.71 | G17: -11117.83 | H17: 2424.05 | I17: 6663.97 | J17: 4792 | K17: 11774
A18: Depreciation | B18: 16710.78 | C18: 17904.99 | D18: 21553.59 | E18: 23590.63 | F18: 21425.43 | G18: 23546.71 | H18: 24835.69 | I18: 24860.36 | J18: 27239 | K18: 23256
A19: Interest | B19: 4889.08 | C19: 4238.01 | D19: 4681.79 | E19: 5758.6 | F19: 7243.33 | G19: 8097.17 | H19: 9311.86 | I19: 10225.48 | J19: 7594 | K19: 5083
... A22: Net profit | B22: 11579.31 | C22: 7454.36 | D22: 8988.91 | E22: -28826.23 | F22: -12070.85 | G22: -13451.39 | H22: -11441.47 | I22: 2414.29 | J22: 31399 | K22: 27830
A23: Dividend Amount | B23: 67.92 | I23: 766.02 | J23: 2301 | K23: 2208
A25: EBITDA | B25: =B22+B21+B19+B18 -> 36204.22 | C25: =C22+C21+C19+C18 -> 32848.59 | D25: =D22+D21+D19+D18 -> 39566.22 | E25: =E22+E21+E19+E18 -> -1914.45 | F25: =F22+F21+F19+F18 -> 16993.16 | G25: =G22+G21+G19+G18 -> 20734.35 | H25: =H22+H21+H19+H18 -> 26937.37 | I25: =I22+I21+I19+I18 -> 38204.19 | ... K25: =K22+K21+K19+K18 -> 66671
A32: Quarters
A33: Report Date | B33: 45016 | C33: 45107 | D33: 45199 | E33: 45291 | F33: 45382 | G33: 45473 | H33: 45565 | I33: 45657 | J33: 45747 | K33: 45838
A34: Sales | B34: 105932.35 | C34: 102236 | D34: 105129 | E34: 110577 | F34: 119033 | G34: 107102 | H34: 101450 | I34: 112608 | J34: 119503 | K34: 104407
A35: Expenses | B35: 92817.95 | C35: 89019 | D35: 91362 | E35: 95159 | F35: 102348 | G35: 91854 | H35: 89291 | I35: 100185 | J35: 102685 | K35: 94183
A36: Other Income | B36: 1452.86 | C36: 895 | D36: 1557 | E36: 1604 | F36: 1412 | G36: 6553 | H36: 1647 | I36: 1700 | J36: 1057 | K36: 1595
A37: Depreciation | B37: 7050.2 | C37: 6633 | D37: 6637 | E37: 6850 | F37: 7143 | G37: 6565 | H37: 6005 | I37: 5399 | J37: 5295 | K37: 5320
A38: Interest | B38: 2641.67 | C38: 2615 | D38: 2652 | E38: 2485 | F38: 1645 | G38: 1471 | H38: 2034 | I38: 1119 | J38: 1076 | K38: 938
A39: Profit before tax | B39: 4875.39 | C39: 4864 | D39: 6035 | E39: 7687 | F39: 9309 | G39: 13765 | H39: 5767 | I39: 7605 | J39: 11504 | K39: 5561
A40: Tax | B40: -620.65 | C40: 1563 | D40: 2203 | E40: 542 | F40: -8219 | G40: 3178 | H40: 2317 | I40: 2120 | J40: 2948 | K40: 1558
A41: Net profit | B41: 5407.79 | C41: 3203 | D41: 3764 | E41: 7025 | F41: 17407 | G41: 10514 | H41: 3343 | I41: 5406 | J41: 8470 | K41: 3924
A42: Operating Profit | B42: 13114.4 | C42: 13217 | D42: 13767 | E42: 15418 | F42: 16685 | G42: 15248 | H42: 12159 | I42: 12423 | J42: 16818 | K42: 10224
A47: BALANCE SHEET
A48: Report Date | B48: 42460 | C48: 42825 | D48: 43190 | E48: 43555 | F48: 43921 | G48: 44286 | H48: 44651 | I48: 45016 | J48: 45382 | K48: 45747
A49: Equity Share Capital | B49: 679.18 | C49: 679.22 | D49: 679.22 | E49: 679.22 | F49: 719.54 | G49: 765.81 | H49: 765.88 | I49: 766.02 | J49: 767 | K49: 736
A50: Reserves | B50: 78273.23 | C50: 57382.67 | D50: 94748.69 | E50: 59500.34 | F50: 62358.99 | G50: 54480.91 | H50: 43795.36 | I50: 44555.77 | J50: 84151 | K50: 115408
A51: Borrowings | B51: 69359.96 | C51: 78603.98 | D51: 88950.47 | E51: 106175.34 | F51: 124787.64 | G51: 142130.57 | H51: 146449.03 | I51: 134113.44 | J51: 107264 | K51: 71540
A52: Other Liabilities | B52: 114871.75 | C52: 135914.49 | D52: 142813.43 | E52: 139348.59 | F52: 132313.22 | G52: 144192.62 | H52: 138051.22 | I52: 155239.2 | J52: 177339 | K52: 189289
A53: Total | B53: 263184.12 | C53: 272580.36 | D53: 327191.81 | E53: 305703.49 | F53: 320179.39 | G53: 341569.91 | H53: 329061.49 | I53: 334674.43 | J53: 369521 | K53: 376973
A54: Net Block | B54: 107231.76 | C54: 95944.08 | D54: 121413.86 | E54: 111234.47 | F54: 127107.14 | G54: 138707.61 | H54: 138855.45 | I54: 132079.76 | J54: 121285 | K54: 115697
A55: Capital Work in Progress | B55: 25918.94 | C55: 33698.84 | D55: 40033.5 | E55: 31883.84 | F55: 35622.29 | G55: 20963.93 | H55: 10251.09 | I55: 14274.5 | J55: 35698 | K55: 65806
A56: Investments | B56: 23767.02 | C56: 20337.92 | D56: 20812.75 | E56: 15770.72 | F56: 16308.48 | G56: 24620.28 | H56: 29379.53 | I56: 26379.16 | J56: 22971 | K56: 35656
A57: Other Assets | B57: 106266.4 | C57: 122599.52 | D57: 144931.7 | E57: 146814.46 | F57: 141141.48 | G57: 157278.09 | H57: 150575.42 | I57: 161941.01 | J57: 189567 | K57: 159814
A58: Total | B58: 263184.12 | C58: 272580.36 | D58: 327191.81 | E58: 305703.49 | F58: 320179.39 | G58: 341569.91 | H58: 329061.49 | I58: 334674.43 | J58: 369521 | K58: 376973
A59: Receivables | B59: 13570.91 | C59: 14075.55 | D59: 19893.3 | E59: 18996.17 | F59: 11172.69 | G59: 12679.08 | H59: 12442.12 | I59: 15737.97 | J59: 16952 | K59: 13248
...

Sheet Common Size Statement
B4: Common Size Income Statement - TATA MOTORS LTD
B6: Particulars | C6: ='DATA SHEET'!B8 -> 42460 | D6: ='DATA SHEET'!C8 -> 42825 | E6: ='DATA SHEET'!D8 -> 43190 | F6: ='DATA SHEET'!E8 -> 43555 | G6: ='DATA SHEET'!F8 -> 43921 | H6: ='DATA SHEET'!G8 -> 44286 | I6: ='DATA SHEET'!H8 -> 44651 | J6: ='DATA SHEET'!I8 -> 45016 | ... L6: ='DATA SHEET'!K8 -> 45747
B8: ='DATA SHEET'!A9 -> Sales | C8: ='DATA SHEET'!B9/'DATA SHEET'!B$9 -> 1 | D8: ='DATA SHEET'!C9/'DATA SHEET'!C$9 -> 1 | E8: ='DATA SHEET'!D9/'DATA SHEET'!D$9 -> 1 | F8: ='DATA SHEET'!E9/'DATA SHEET'!E$9 -> 1 | G8: ='DATA SHEET'!F9/'DATA SHEET'!F$9 -> 1 | H8: ='DATA SHEET'!G9/'DATA SHEET'!G$9 -> 1 | I8: ='DATA SHEET'!H9/'DATA SHEET'!H$9 -> 1 | J8: ='DATA SHEET'!I9/'DATA SHEET'!I$9 -> 1 | ... L8: ='DATA SHEET'!K9/'DATA SHEET'!K$9 -> 1
B9: ='DATA SHEET'!A10 -> Raw Material Cost | C9: ='DATA SHEET'!B10/'DATA SHEET'!B$9 -> 0.60844786 | D9: ='DATA SHEET'!C10/'DATA SHEET'!C$9 -> 0.64256171 | E9: ='DATA SHEET'!D10/'DATA SHEET'!D$9 -> 0.64447357 | F9: ='DATA SHEET'!E10/'DATA SHEET'!E$9 -> 0.64340246 | G9: ='DATA SHEET'!F10/'DATA SHEET'!F$9 -> 0.63163559 | H9: ='DATA SHEET'!G10/'DATA SHEET'!G$9 -> 0.6149343 | I9: ='DATA SHEET'!H10/'DATA SHEET'!H$9 -> 0.64389657 | J9: ='DATA SHEET'!I10/'DATA SHEET'!I$9 -> 0.66842005 | ... L9: ='DATA SHEET'!K10/'DATA SHEET'!K$9 -> 0.611674
B10: ='DATA SHEET'!A11 -> Change in Inventory | C10: ='DATA SHEET'!B11/'DATA SHEET'!B$9 -> 0.010075204 | D10: ='DATA SHEET'!C11/'DATA SHEET'!C$9 -> 0.027438359 | E10: ='DATA SHEET'!D11/'DATA SHEET'!D$9 -> 0.007019642 | F10: ='DATA SHEET'!E11/'DATA SHEET'!E$9 -> -0.0068003275 | G10: ='DATA SHEET'!F11/'DATA SHEET'!F$9 -> -0.008546395 | H10: ='DATA SHEET'!G11/'DATA SHEET'!G$9 -> -0.018752035 | I10: ='DATA SHEET'!H11/'DATA SHEET'!H$9 -> -0.0057118668 | J10: ='DATA SHEET'!I11/'DATA SHEET'!I$9 -> 0.01382103 | ... L10: ='DATA SHEET'!K11/'DATA SHEET'!K$9 -> -0.0064499255
B11: ='DATA SHEET'!A12 -> Power and Fuel | C11: ='DATA SHEET'!B12/'DATA SHEET'!B$9 -> 0.0041884213 | D11: ='DATA SHEET'!C12/'DATA SHEET'!C$9 -> 0.0043005273 | E11: ='DATA SHEET'!D12/'DATA SHEET'!D$9 -> 0.004486633 | F11: ='DATA SHEET'!E12/'DATA SHEET'!E$9 -> 0.0052524952 | G11: ='DATA SHEET'!F12/'DATA SHEET'!F$9 -> 0.0048452899 | H11: ='DATA SHEET'!G12/'DATA SHEET'!G$9 -> 0.0044551377 | I11: ='DATA SHEET'!H12/'DATA SHEET'!H$9 -> 0.0078228109 | J11: ='DATA SHEET'!I12/'DATA SHEET'!I$9 -> 0.007264653 | ... L11: ='DATA SHEET'!K12/'DATA SHEET'!K$9 -> 0.0055561241
B12: ='DATA SHEET'!A13 -> Other Mfr. Exp | C12: ='DATA SHEET'!B13/'DATA SHEET'!B$9 -> 0.044320546 | D12: ='DATA SHEET'!C13/'DATA SHEET'!C$9 -> 0.037329068 | E12: ='DATA SHEET'!D13/'DATA SHEET'!D$9 -> 0.037632111 | F12: ='DATA SHEET'!E13/'DATA SHEET'!E$9 -> 0.038731543 | G12: ='DATA SHEET'!F13/'DATA SHEET'!F$9 -> 0.044208832 | H12: ='DATA SHEET'!G13/'DATA SHEET'!G$9 -> 0.033119871 | I12: ='DATA SHEET'!H13/'DATA SHEET'!H$9 -> 0.033856195 | J12: ='DATA SHEET'!I13/'DATA SHEET'!I$9 -> 0.03400894 | ... L12: ='DATA SHEET'!K13/'DATA SHEET'!K$9 -> 0.042786477
B13: ='DATA SHEET'!A14 -> Employee Cost | C13: ='DATA SHEET'!B14/'DATA SHEET'!B$9 -> 0.10577314 | D13: ='DATA SHEET'!C14/'DATA SHEET'!C$9 -> 0.10505627 | E13: ='DATA SHEET'!D14/'DATA SHEET'!D$9 -> 0.10392742 | F13: ='DATA SHEET'!E14/'DATA SHEET'!E$9 -> 0.1101015 | G13: ='DATA SHEET'!F14/'DATA SHEET'!F$9 -> 0.11659263 | H13: ='DATA SHEET'!G14/'DATA SHEET'!G$9 -> 0.11068479 | I13: ='DATA SHEET'!H14/'DATA SHEET'!H$9 -> 0.11064148 | J13: ='DATA SHEET'!I14/'DATA SHEET'!I$9 -> 0.097277205 | ... L13: ='DATA SHEET'!K14/'DATA SHEET'!K$9 -> 0.10863667
B14: ='DATA SHEET'!A15 -> Selling and admin | C14: ='DATA SHEET'!B15/'DATA SHEET'!B$9 -> 0.080542957 | D14: ='DATA SHEET'!C15/'DATA SHEET'!C$9 -> 0.11138381 | E14: ='DATA SHEET'!D15/'DATA SHEET'!D$9 -> 0.10634378 | F14: ='DATA SHEET'!E15/'DATA SHEET'!E$9 -> 0.10836581 | G14: ='DATA SHEET'!F15/'DATA SHEET'!F$9 -> 0.11203335 | H14: ='DATA SHEET'!G15/'DATA SHEET'!G$9 -> 0.092138806 | I14: ='DATA SHEET'!H15/'DATA SHEET'!H$9 -> 0.10488425 | J14: ='DATA SHEET'!I15/'DATA SHEET'!I$9 -> 0.10070091 | ... L14: ='DATA SHEET'!K15/'DATA SHEET'!K$9 -> 0.10711743
B15: ='DATA SHEET'!A16 -> Other Expenses | C15: ='DATA SHEET'!B16/'DATA SHEET'!B$9 -> 0.026183832 | D15: ='DATA SHEET'!C16/'DATA SHEET'!C$9 -> 0.017094283 | E15: ='DATA SHEET'!D16/'DATA SHEET'!D$9 -> 0.0022582367 | F15: ='DATA SHEET'!E16/'DATA SHEET'!E$9 -> 0.0056592338 | G15: ='DATA SHEET'!F16/'DATA SHEET'!F$9 -> 0.013239885 | H15: ='DATA SHEET'!G16/'DATA SHEET'!G$9 -> -0.0033407828 | I15: ='DATA SHEET'!H16/'DATA SHEET'!H$9 -> 0.0044105011 | J15: ='DATA SHEET'!I16/'DATA SHEET'!I$9 -> 0.014187308 | ... L15: ='DATA SHEET'!K16/'DATA SHEET'!K$9 -> -0.0077985877
B16: ='DATA SHEET'!A17 -> Other Income | C16: ='DATA SHEET'!B17/'DATA SHEET'!B$9 -> -0.0097771947 | D16: ='DATA SHEET'!C17/'DATA SHEET'!C$9 -> 0.0069304854 | E16: ='DATA SHEET'!D17/'DATA SHEET'!D$9 -> 0.020348895 | F16: ='DATA SHEET'!E17/'DATA SHEET'!E$9 -> -0.088383094 | G16: ='DATA SHEET'!F17/'DATA SHEET'!F$9 -> 0.00038959203 | H16: ='DATA SHEET'!G17/'DATA SHEET'!G$9 -> -0.044507861 | I16: ='DATA SHEET'!H17/'DATA SHEET'!H$9 -> 0.0087053995 | J16: ='DATA SHEET'!I17/'DATA SHEET'!I$9 -> 0.019261868 | ... L16: ='DATA SHEET'!K17/'DATA SHEET'!K$9 -> 0.026777653
B17: ='DATA SHEET'!A18 -> Depreciation | C17: ='DATA SHEET'!B18/'DATA SHEET'!B$9 -> 0.061201426 | D17: ='DATA SHEET'!C18/'DATA SHEET'!C$9 -> 0.066390387 | E17: ='DATA SHEET'!D18/'DATA SHEET'!D$9 -> 0.073927472 | F17: ='DATA SHEET'!E18/'DATA SHEET'!E$9 -> 0.078130605 | G17: ='DATA SHEET'!F18/'DATA SHEET'!F$9 -> 0.082068398 | H17: ='DATA SHEET'!G18/'DATA SHEET'!G$9 -> 0.094264231 | I17: ='DATA SHEET'!H18/'DATA SHEET'!H$9 -> 0.089191478 | J17: ='DATA SHEET'!I18/'DATA SHEET'!I$9 -> 0.071857611 | ... L17: ='DATA SHEET'!K18/'DATA SHEET'!K$9 -> 0.052891209
B18: ='DATA SHEET'!A19 -> Interest | C18: ='DATA SHEET'!B19/'DATA SHEET'!B$9 -> 0.017905727 | D18: ='DATA SHEET'!C19/'DATA SHEET'!C$9 -> 0.01571423 | E18: ='DATA SHEET'!D19/'DATA SHEET'!D$9 -> 0.016058248 | F18: ='DATA SHEET'!E19/'DATA SHEET'!E$9 -> 0.019072102 | G18: ='DATA SHEET'!F19/'DATA SHEET'!F$9 -> 0.027744997 | H18: ='DATA SHEET'!G19/'DATA SHEET'!G$9 -> 0.032415293 | I18: ='DATA SHEET'!H19/'DATA SHEET'!H$9 -> 0.033441332 | J18: ='DATA SHEET'!I19/'DATA SHEET'!I$9 -> 0.029556232 | ... L18: ='DATA SHEET'!K19/'DATA SHEET'!K$9 -> 0.011560286
B19: ='DATA SHEET'!A20 -> Profit before tax | C19: ='DATA SHEET'!B20/'DATA SHEET'!B$9 -> 0.051734106 | D19: ='DATA SHEET'!C20/'DATA SHEET'!C$9 -> 0.034538557 | E19: ='DATA SHEET'!D20/'DATA SHEET'!D$9 -> 0.038261059 | F19: ='DATA SHEET'!E20/'DATA SHEET'!E$9 -> -0.10389917 | G19: ='DATA SHEET'!F20/'DATA SHEET'!F$9 -> -0.040525768 | H19: ='DATA SHEET'!G20/'DATA SHEET'!G$9 -> -0.041931546 | I19: ='DATA SHEET'!H20/'DATA SHEET'!H$9 -> -0.025151083 | J19: ='DATA SHEET'!I20/'DATA SHEET'!I$9 -> 0.0098099827 | ... L19: ='DATA SHEET'!K20/'DATA SHEET'!K$9 -> 0.087904115
... B22: ='DATA SHEET'!A23 -> Dividend Amount | C22: ='DATA SHEET'!B23/'DATA SHEET'!B$9 -> 0.00024874966 | D22: ='DATA SHEET'!C23/'DATA SHEET'!C$9 -> 0 | E22: ='DATA SHEET'!D23/'DATA SHEET'!D$9 -> 0 | F22: ='DATA SHEET'!E23/'DATA SHEET'!E$9 -> 0 | G22: ='DATA SHEET'!F23/'DATA SHEET'!F$9 -> 0 | H22: ='DATA SHEET'!G23/'DATA SHEET'!G$9 -> 0 | I22: ='DATA SHEET'!H23/'DATA SHEET'!H$9 -> 0 | J22: ='DATA SHEET'!I23/'DATA SHEET'!I$9 -> 0.002214142 | ... L22: ='DATA SHEET'!K23/'DATA SHEET'!K$9 -> 0.0050216627
B23: EBITDA | C23: ='DATA SHEET'!B25/'DATA SHEET'!B$9 -> 0.13259404 | D23: ='DATA SHEET'!C25/'DATA SHEET'!C$9 -> 0.12180016 | E23: ='DATA SHEET'!D25/'DATA SHEET'!D$9 -> 0.13570967 | F23: ='DATA SHEET'!E25/'DATA SHEET'!E$9 -> -0.0063405317 | G23: ='DATA SHEET'!F25/'DATA SHEET'!F$9 -> 0.065090942 | H23: ='DATA SHEET'!G25/'DATA SHEET'!G$9 -> 0.083005548 | I23: ='DATA SHEET'!H25/'DATA SHEET'!H$9 -> 0.096739163 | J23: ='DATA SHEET'!I25/'DATA SHEET'!I$9 -> 0.11042728 | ... L23: ='DATA SHEET'!K25/'DATA SHEET'!K$9 -> 0.15163011
B26: Common Size Balance Sheet - TATA MOTORS LTD
B28: =B6 -> Particulars | C28: ='DATA SHEET'!B48 -> 42460 | D28: ='DATA SHEET'!C48 -> 42825 | E28: ='DATA SHEET'!D48 -> 43190 | F28: ='DATA SHEET'!E48 -> 43555 | G28: ='DATA SHEET'!F48 -> 43921 | H28: ='DATA SHEET'!G48 -> 44286 | I28: ='DATA SHEET'!H48 -> 44651 | J28: ='DATA SHEET'!I48 -> 45016 | ... L28: ='DATA SHEET'!K48 -> 45747
B30: Total Liablities | C30: ='DATA SHEET'!B53/'DATA SHEET'!B$53 -> 1 | D30: ='DATA SHEET'!C53/'DATA SHEET'!C$53 -> 1 | E30: ='DATA SHEET'!D53/'DATA SHEET'!D$53 -> 1 | F30: ='DATA SHEET'!E53/'DATA SHEET'!E$53 -> 1 | G30: ='DATA SHEET'!F53/'DATA SHEET'!F$53 -> 1 | H30: ='DATA SHEET'!G53/'DATA SHEET'!G$53 -> 1 | I30: ='DATA SHEET'!H53/'DATA SHEET'!H$53 -> 1 | J30: ='DATA SHEET'!I53/'DATA SHEET'!I$53 -> 1 | ... L30: ='DATA SHEET'!K53/'DATA SHEET'!K$53 -> 1
B31: ='DATA SHEET'!A49 -> Equity Share Capital | C31: ='DATA SHEET'!B49/'DATA SHEET'!B$53 -> 0.0025806268 | D31: ='DATA SHEET'!C49/'DATA SHEET'!C$53 -> 0.0024918156 | E31: ='DATA SHEET'!D49/'DATA SHEET'!D$53 -> 0.0020759077 | F31: ='DATA SHEET'!E49/'DATA SHEET'!E$53 -> 0.0022218261 | G31: ='DATA SHEET'!F49/'DATA SHEET'!F$53 -> 0.0022473027 | H31: ='DATA SHEET'!G49/'DATA SHEET'!G$53 -> 0.00224203 | I31: ='DATA SHEET'!H49/'DATA SHEET'!H$53 -> 0.0023274677 | J31: ='DATA SHEET'!I49/'DATA SHEET'!I$53 -> 0.0022888513 | ... L31: ='DATA SHEET'!K49/'DATA SHEET'!K$53 -> 0.0019523945
B32: ='DATA SHEET'!A50 -> Reserves | C32: ='DATA SHEET'!B50/'DATA SHEET'!B$53 -> 0.29740864 | D32: ='DATA SHEET'!C50/'DATA SHEET'!C$53 -> 0.21051652 | E32: ='DATA SHEET'!D50/'DATA SHEET'!D$53 -> 0.28958148 | F32: ='DATA SHEET'!E50/'DATA SHEET'!E$53 -> 0.19463415 | G32: ='DATA SHEET'!F50/'DATA SHEET'!F$53 -> 0.19476266 | H32: ='DATA SHEET'!G50/'DATA SHEET'!G$53 -> 0.15950149 | I32: ='DATA SHEET'!H50/'DATA SHEET'!H$53 -> 0.13309172 | J32: ='DATA SHEET'!I50/'DATA SHEET'!I$53 -> 0.13313168 | ... L32: ='DATA SHEET'!K50/'DATA SHEET'!K$53 -> 0.30614394
B33: ='DATA SHEET'!A51 -> Borrowings | C33: ='DATA SHEET'!B51/'DATA SHEET'!B$53 -> 0.26354158 | D33: ='DATA SHEET'!C51/'DATA SHEET'!C$53 -> 0.28836993 | E33: ='DATA SHEET'!D51/'DATA SHEET'!D$53 -> 0.27186032 | F33: ='DATA SHEET'!E51/'DATA SHEET'!E$53 -> 0.34731478 | G33: ='DATA SHEET'!F51/'DATA SHEET'!F$53 -> 0.38974289 | H33: ='DATA SHEET'!G51/'DATA SHEET'!G$53 -> 0.41610975 | I33: ='DATA SHEET'!H51/'DATA SHEET'!H$53 -> 0.44505065 | J33: ='DATA SHEET'!I51/'DATA SHEET'!I$53 -> 0.40072807 | ... L33: ='DATA SHEET'!K51/'DATA SHEET'!K$53 -> 0.18977486
B34: ='DATA SHEET'!A52 -> Other Liabilities | C34: ='DATA SHEET'!B52/'DATA SHEET'!B$53 -> 0.43646915 | D34: ='DATA SHEET'!C52/'DATA SHEET'!C$53 -> 0.49862173 | E34: ='DATA SHEET'!D52/'DATA SHEET'!D$53 -> 0.43648229 | F34: ='DATA SHEET'!E52/'DATA SHEET'!E$53 -> 0.45582924 | G34: ='DATA SHEET'!F52/'DATA SHEET'!F$53 -> 0.41324715 | H34: ='DATA SHEET'!G52/'DATA SHEET'!G$53 -> 0.42214673 | I34: ='DATA SHEET'!H52/'DATA SHEET'!H$53 -> 0.41953016 | J34: ='DATA SHEET'!I52/'DATA SHEET'!I$53 -> 0.46385139 | ... L34: ='DATA SHEET'!K52/'DATA SHEET'!K$53 -> 0.5021288
B36: Total Assets | C36: ='DATA SHEET'!B66/'DATA SHEET'!B$66 -> 1 | D36: ='DATA SHEET'!C66/'DATA SHEET'!C$66 -> 1 | E36: ='DATA SHEET'!D66/'DATA SHEET'!D$66 -> 1 | F36: ='DATA SHEET'!E66/'DATA SHEET'!E$66 -> 1 | G36: ='DATA SHEET'!F66/'DATA SHEET'!F$66 -> 1 | H36: ='DATA SHEET'!G66/'DATA SHEET'!G$66 -> 1 | I36: ='DATA SHEET'!H66/'DATA SHEET'!H$66 -> 1 | J36: ='DATA SHEET'!I66/'DATA SHEET'!I$66 -> 1 | ... L36: ='DATA SHEET'!K66/'DATA SHEET'!K$66 -> 1
B37: ='DATA SHEET'!A54 -> Net Block | C37: ='DATA SHEET'!B54/'DATA SHEET'!B$66 -> 0.40744008 | D37: ='DATA SHEET'!C54/'DATA SHEET'!C$66 -> 0.35198457 | E37: ='DATA SHEET'!D54/'DATA SHEET'!D$66 -> 0.37107854 | F37: ='DATA SHEET'!E54/'DATA SHEET'!E$66 -> 0.36386392 | G37: ='DATA SHEET'!F54/'DATA SHEET'!F$66 -> 0.39698726 | H37: ='DATA SHEET'!G54/'DATA SHEET'!G$66 -> 0.40608849 | I37: ='DATA SHEET'!H54/'DATA SHEET'!H$66 -> 0.42197417 | J37: ='DATA SHEET'!I54/'DATA SHEET'!I$66 -> 0.39465148 | ... L37: ='DATA SHEET'!K54/'DATA SHEET'!K$66 -> 0.30691057
B38: ='DATA SHEET'!A55 -> Capital Work in Progress | C38: ='DATA SHEET'!B55/'DATA SHEET'!B$66 -> 0.098482158 | D38: ='DATA SHEET'!C55/'DATA SHEET'!C$66 -> 0.12362901 | E38: ='DATA SHEET'!D55/'DATA SHEET'!D$66 -> 0.12235484 | F38: ='DATA SHEET'!E55/'DATA SHEET'!E$66 -> 0.10429662 | G38: ='DATA SHEET'!F55/'DATA SHEET'!F$66 -> 0.11125729 | H38: ='DATA SHEET'!G55/'DATA SHEET'!G$66 -> 0.061375225 | I38: ='DATA SHEET'!H55/'DATA SHEET'!H$66 -> 0.031152506 | J38: ='DATA SHEET'!I55/'DATA SHEET'!I$66 -> 0.042651899 | ... L38: ='DATA SHEET'!K55/'DATA SHEET'!K$66 -> 0.17456423
B39: ='DATA SHEET'!A56 -> Investments | C39: ='DATA SHEET'!B56/'DATA SHEET'!B$66 -> 0.090305676 | D39: ='DATA SHEET'!C56/'DATA SHEET'!C$66 -> 0.074612566 | E39: ='DATA SHEET'!D56/'DATA SHEET'!D$66 -> 0.063610241 | F39: ='DATA SHEET'!E56/'DATA SHEET'!E$66 -> 0.051588289 | G39: ='DATA SHEET'!F56/'DATA SHEET'!F$66 -> 0.050935446 | H39: ='DATA SHEET'!G56/'DATA SHEET'!G$66 -> 0.072079768 | I39: ='DATA SHEET'!H56/'DATA SHEET'!H$66 -> 0.089282796 | J39: ='DATA SHEET'!I56/'DATA SHEET'!I$66 -> 0.078820363 | ... L39: ='DATA SHEET'!K56/'DATA SHEET'!K$66 -> 0.094585023
B40: ='DATA SHEET'!A57 -> Other Assets | C40: ='DATA SHEET'!B68/'DATA SHEET'!B$66 -> 0.11239037 | D40: ='DATA SHEET'!C68/'DATA SHEET'!C$66 -> 0.13706336 | E40: ='DATA SHEET'!D68/'DATA SHEET'!D$66 -> 0.14757967 | F40: ='DATA SHEET'!E68/'DATA SHEET'!E$66 -> 0.18369349 | G40: ='DATA SHEET'!F68/'DATA SHEET'!F$66 -> 0.18360001 | H40: ='DATA SHEET'!G68/'DATA SHEET'!G$66 -> 0.1806891 | I40: ='DATA SHEET'!H68/'DATA SHEET'!H$66 -> 0.18909466 | J40: ='DATA SHEET'!I68/'DATA SHEET'!I$66 -> 0.20447361 | ... L40: ='DATA SHEET'!K68/'DATA SHEET'!K$66 -> 0.15508538
B41: Receivables | C41: ='DATA SHEET'!B59/'DATA SHEET'!B$66 -> 0.051564319 | D41: ='DATA SHEET'!C59/'DATA SHEET'!C$66 -> 0.051638166 | E41: ='DATA SHEET'!D59/'DATA SHEET'!D$66 -> 0.060800116 | F41: ='DATA SHEET'!E59/'DATA SHEET'!E$66 -> 0.062139199 | G41: ='DATA SHEET'!F59/'DATA SHEET'!F$66 -> 0.034895094 | H41: ='DATA SHEET'!G59/'DATA SHEET'!G$66 -> 0.037120014 | I41: ='DATA SHEET'!H59/'DATA SHEET'!H$66 -> 0.037810927 | J41: ='DATA SHEET'!I59/'DATA SHEET'!I$66 -> 0.047024716 | ... L41: ='DATA SHEET'!K59/'DATA SHEET'!K$66 -> 0.0351431
B42: Inventory | C42: ='DATA SHEET'!B60/'DATA SHEET'!B$66 -> 0.12407941 | D42: ='DATA SHEET'!C60/'DATA SHEET'!C$66 -> 0.12871547 | E42: ='DATA SHEET'!D60/'DATA SHEET'!D$66 -> 0.12878571 | F42: ='DATA SHEET'!E60/'DATA SHEET'!E$66 -> 0.12761951 | G42: ='DATA SHEET'!F60/'DATA SHEET'!F$66 -> 0.11698717 | H42: ='DATA SHEET'!G60/'DATA SHEET'!G$66 -> 0.10565506 | I42: ='DATA SHEET'!H60/'DATA SHEET'!H$66 -> 0.10709348 | J42: ='DATA SHEET'!I60/'DATA SHEET'!I$66 -> 0.12177623 | ... L42: ='DATA SHEET'!K60/'DATA SHEET'!K$66 -> 0.12539094
B43: Cash & Bank | C43: ='DATA SHEET'!B61/'DATA SHEET'!B$66 -> 0.11573799 | D43: ='DATA SHEET'!C61/'DATA SHEET'!C$66 -> 0.13235686 | E43: ='DATA SHEET'!D61/'DATA SHEET'!D$66 -> 0.10579088 | F43: ='DATA SHEET'!E61/'DATA SHEET'!E$66 -> 0.10679898 | G43: ='DATA SHEET'!F61/'DATA SHEET'!F$66 -> 0.10533773 | H43: ='DATA SHEET'!G61/'DATA SHEET'!G$66 -> 0.13699234 | I43: ='DATA SHEET'!H61/'DATA SHEET'!H$66 -> 0.12359146 | J43: ='DATA SHEET'!I61/'DATA SHEET'!I$66 -> 0.1106017 | ... L43: ='DATA SHEET'!K61/'DATA SHEET'!K$66 -> 0.10832076
