Workbook

Sheet DATA ROOM 1
B2: Particulars | C2: 42064 | D2: 42430 | E2: 42795 | F2: 43160 | G2: 43525 | H2: 43891 | I2: 44256 | J2: 44621 | K2: 44986 | L2: 45352 | M2: 45717
B4: Equity Capital | C4: 96 | D4: 96 | E4: 96 | F4: 96 | G4: 96 | H4: 96 | I4: 96 | J4: 96 | K4: 96 | L4: 96 | M4: 96
B5: Reserves | C5: 3943 | D5: 4646 | E5: 6429 | F5: 7508 | G5: 8314 | H5: 9375 | I5: 10034 | J5: 12710 | K5: 13716 | L5: 15896 | M5: 18632
B6: Borrowings -
B7: Long term Borrowings | C7: 41 | D7: 78 | E7: 73 | F7: 41 | G7: 28 | H7: 19 | I7: 19 | J7: 15 | K7: 45 | L7: 76 | M7: 54
B8: Short term Borrowings | C8: 199 | D8: 332 | E8: 231 | F8: 504 | G8: 492 | H8: 597 | I8: 321 | J8: 326 | K8: 731 | L8: 896 | M8: 1053
B9: Lease Liabilities | C9: 0 | D9: 0 | E9: 0 | F9: 0 | G9: 0 | H9: 693 | I9: 764 | J9: 745 | K9: 811 | L9: 960 | M9: 1367
B10: Other Borrowings | C10: 9 | D10: 8 | E10: 20 | F10: 15 | G10: 13 | H10: 11 | I10: 15 | J10: 8 | K10: 0 | L10: 0 | M10: 0
B11: Other Liabilities -
B12: Non controlling int | C12: 246 | D12: 264 | E12: 384 | F12: 375 | G12: 328 | H12: 361 | I12: 404 | J12: 423 | K12: 388 | L12: 454 | M12: 695
B13: Trade Payables | C13: 1746 | D13: 1549 | E13: 1565 | F13: 1923 | G13: 2160 | H13: 2394 | I13: 2137 | J13: 3379 | K13: 4164 | L13: 3635 | M13: 3831
B14: Advance from Customers | C14: 0 | D14: 5 | E14: 12 | F14: 17 | G14: 16 | H14: 13 | I14: 29 | J14: 41 | K14: 76 | L14: 108 | M14: 154
B15: Other liability items | C15: 1795 | D15: 1937 | E15: 1750 | F15: 1925 | G15: 2316 | H15: 2690 | I15: 2320 | J15: 2613 | K15: 2932 | L15: 3657 | M15: 4017
B16: Total Liabilities | C16: 8075 | D16: 8914 | E16: 10559 | F16: 12405 | G16: 13763 | H16: 16249 | I16: 16138 | J16: 20355 | K16: 22958 | L16: 25779 | M16: 29901
B18: Fixed Assets -
B19: Land | C19: 247 | D19: 251 | E19: 429 | F19: 408 | G19: 586 | H19: 605 | I19: 640 | J19: 644 | K19: 644 | L19: 804 | M19: 1126
B20: Building | C20: 931 | D20: 962 | E20: 923 | F20: 931 | G20: 957 | H20: 2402 | I20: 2257 | J20: 2249 | K20: 2325 | L20: 2883 | M20: 3390
B21: Plant Machinery | C21: 2054 | D21: 2132 | E21: 1793 | F21: 1980 | G21: 2157 | H21: 4006 | I21: 4208 | J21: 4340 | K21: 4531 | L21: 4825 | M21: 5422
B22: Equipments | C22: 155 | D22: 171 | E22: 97 | F22: 119 | G22: 200 | H22: 221 | I22: 241 | J22: 243 | K22: 253 | L22: 270 | M22: 298
B23: Furniture n fittings | C23: 71 | D23: 83 | E23: 49 | F23: 59 | G23: 72 | H23: 88 | I23: 94 | J23: 99 | K23: 113 | L23: 146 | M23: 175
B24: Vehicles | C24: 14 | D24: 18 | E24: 11 | F24: 14 | G24: 27 | H24: 47 | I24: 43 | J24: 38 | K24: 32 | L24: 36 | M24: 40
B25: Intangible Assets | C25: 203 | D25: 351 | E25: 339 | F25: 276 | G25: 468 | H25: 512 | I25: 505 | J25: 476 | K25: 345 | L25: 422 | M25: 850
B26: Other fixed assets | C26: 128 | D26: 145 | E26: 103 | F26: 128 | G26: 238 | H26: 261 | I26: 293 | J26: 302 | K26: 294 | L26: 289 | M26: 321
B27: Gross Block | C27: 3804 | D27: 4112 | E27: 3744 | F27: 3914 | G27: 4705 | H27: 8141 | I27: 8282 | J27: 8392 | K27: 8538 | L27: 9676 | M27: 11622
B28: Accumulated Depriciation | C28: 1242 | D28: 1452 | E28: 327 | F28: 610 | G28: 973 | H28: 1644 | I28: 2010 | J28: 2533 | K28: 3019 | L28: 3905 | M28: 4475
B29: Net Block | C29: =C27-C28 -> 2562 | D29: =D27-D28 -> 2660 | E29: =E27-E28 -> 3417 | F29: =F27-F28 -> 3304 | G29: =G27-G28 -> 3732 | H29: =H27-H28 -> 6497 | I29: =I27-I28 -> 6272 | J29: =J27-J28 -> 5859 | ... M29: =M27-M28 -> 7147
B31: CWIP | C31: 72 | D31: 196 | E31: 107 | F31: 258 | G31: 1405 | H31: 210 | I31: 140 | J31: 183 | K31: 426 | L31: 1020 | M31: 2698
B32: Investments | C32: 1424 | D32: 1588 | E32: 2712 | F32: 2652 | G32: 2141 | H32: 2569 | I32: 2019 | J32: 4737 | K32: 3248 | L32: 4262 | M32: 4588
B34: Other Assets -
B35: Inventories | C35: 2070 | D35: 2259 | E35: 1998 | F35: 2627 | G35: 2658 | H35: 3150 | I35: 3390 | J35: 3799 | K35: 6153 | L35: 6211 | M35: 5923
B36: Trade receivables + | C36: 1110 | D36: 1182 | E36: 1187 | F36: 1447 | G36: 1731 | H36: 1907 | I36: 1795 | J36: 2602 | K36: 3871 | L36: 4637 | M36: 4889
B37: Cash Equivalents | C37: 229 | D37: 204 | E37: 424 | F37: 801 | G37: 405 | H37: 445 | I37: 783 | J37: 611 | K37: 864 | L37: 844 | M37: 1084
B38: Loans n Advances | C38: 7 | D38: 8 | E38: 9 | F38: 14 | G38: 13 | H38: 16 | I38: 12 | J38: 12 | K38: 8 | L38: 12 | M38: 17
B39: Other asset items | C39: 603 | D39: 817 | E39: 705 | F39: 1303 | G39: 1678 | H39: 1456 | I39: 1727 | J39: 2554 | K39: 2869 | L39: 3024 | M39: 3555
B40: Total Assets | C40: 8075 | D40: 8914 | E40: 10559 | F40: 12405 | G40: 13763 | H40: 16249 | I40: 16138 | J40: 20355 | K40: 22958 | L40: 25779 | M40: 29901
B44: Cash from Operating Activity - | C44: 1402 | D44: 1188 | E44: 2243 | F44: 1527 | G44: 2113 | H44: 2470 | I44: 3038 | J44: 3683 | K44: 986 | L44: 4193 | M44: 6104
B45: Profit from operations | C45: 2051 | D45: 2271 | E45: 2848 | F45: 3056 | G45: 3274 | H45: 3861 | I45: 4380 | J45: 4970 | K45: 4957 | L45: 6460 | M45: 7929
B46: Receivables | C46: -254 | D46: -155 | E46: -146 | F46: -475 | G46: -483 | H46: -205 | I46: 160 | J46: -1342 | K46: -1326 | L46: -834 | M46: -362
B47: Inventory | C47: -231 | D47: -144 | E47: 202 | F47: -629 | G47: -39 | H47: -492 | I47: -251 | J47: -409 | K47: -2354 | L47: -56 | M47: 315
B48: Payables | C48: 317 | D48: -151 | E48: 142 | F48: 501 | G48: 442 | H48: 287 | I48: -241 | J48: 1544 | K48: 644 | L48: -539 | M48: 269
...

Sheet INTRINSIC GROWTH 
B3: Calculation of ROIC | G3: ='DATA ROOM 1'!I2 -> 44256 | H3: ='DATA ROOM 1'!J2 -> 44621 | I3: ='DATA ROOM 1'!K2 -> 44986 | J3: ='DATA ROOM 1'!L2 -> 45352 | K3: ='DATA ROOM 1'!M2 -> 45717
B5: Current Assets
B6: ='DATA ROOM 1'!B35 -> Inventories | G6: ='DATA ROOM 1'!I35 -> 3390 | H6: ='DATA ROOM 1'!J35 -> 3799 | I6: ='DATA ROOM 1'!K35 -> 6153 | J6: ='DATA ROOM 1'!L35 -> 6211 | K6: ='DATA ROOM 1'!M35 -> 5923
B7: ='DATA ROOM 1'!B36 -> Trade receivables + | G7: ='DATA ROOM 1'!I36 -> 1795 | H7: ='DATA ROOM 1'!J36 -> 2602 | I7: ='DATA ROOM 1'!K36 -> 3871 | J7: ='DATA ROOM 1'!L36 -> 4637 | K7: ='DATA ROOM 1'!M36 -> 4889
B8: ='DATA ROOM 1'!B38 -> Loans n Advances | G8: ='DATA ROOM 1'!I38 -> 12 | H8: ='DATA ROOM 1'!J38 -> 12 | I8: ='DATA ROOM 1'!K38 -> 8 | J8: ='DATA ROOM 1'!L38 -> 12 | K8: ='DATA ROOM 1'!M38 -> 17
B9: ='DATA ROOM 1'!B39 -> Other asset items | G9: ='DATA ROOM 1'!I39 -> 1727 | H9: ='DATA ROOM 1'!J39 -> 2554 | I9: ='DATA ROOM 1'!K39 -> 2869 | J9: ='DATA ROOM 1'!L39 -> 3024 | K9: ='DATA ROOM 1'!M39 -> 3555
B10: Total Current Assets | G10: =SUM(G6:G9) -> 6924 | H10: =SUM(H6:H9) -> 8967 | I10: =SUM(I6:I9) -> 12901 | J10: =SUM(J6:J9) -> 13884 | K10: =SUM(K6:K9) -> 14384
B13: Current Liablities
B14: ='DATA ROOM 1'!B13 -> Trade Payables | G14: ='DATA ROOM 1'!I13 -> 2137 | H14: ='DATA ROOM 1'!J13 -> 3379 | I14: ='DATA ROOM 1'!K13 -> 4164 | J14: ='DATA ROOM 1'!L13 -> 3635 | K14: ='DATA ROOM 1'!M13 -> 3831
B15: ='DATA ROOM 1'!B14 -> Advance from Customers | G15: ='DATA ROOM 1'!I14 -> 29 | H15: ='DATA ROOM 1'!J14 -> 41 | I15: ='DATA ROOM 1'!K14 -> 76 | J15: ='DATA ROOM 1'!L14 -> 108 | K15: ='DATA ROOM 1'!M14 -> 154
B16: ='DATA ROOM 1'!B15 -> Other liability items | G16: ='DATA ROOM 1'!I15 -> 2320 | H16: ='DATA ROOM 1'!J15 -> 2613 | I16: ='DATA ROOM 1'!K15 -> 2932 | J16: ='DATA ROOM 1'!L15 -> 3657 | K16: ='DATA ROOM 1'!M15 -> 4017
B17: Total Current Assets | G17: =SUM(G14:G16) -> 4486 | H17: =SUM(H14:H16) -> 6033 | I17: =SUM(I14:I16) -> 7172 | J17: =SUM(J14:J16) -> 7400 | K17: =SUM(K14:K16) -> 8002
A20: # | B20: Net Working Capital | G20: =G10-G18 -> 6924 | H20: =H10-H18 -> 8967 | I20: =I10-I18 -> 12901 | J20: =J10-J18 -> 13884 | K20: =K10-K18 -> 14384
B22: Non Current Assets
B23: ='DATA ROOM 1'!B19 -> Land | G23: ='DATA ROOM 1'!I19 -> 640 | H23: ='DATA ROOM 1'!J19 -> 644 | I23: ='DATA ROOM 1'!K19 -> 644 | J23: ='DATA ROOM 1'!L19 -> 804 | K23: ='DATA ROOM 1'!M19 -> 1126
B24: ='DATA ROOM 1'!B20 -> Building | G24: ='DATA ROOM 1'!I20 -> 2257 | H24: ='DATA ROOM 1'!J20 -> 2249 | I24: ='DATA ROOM 1'!K20 -> 2325 | J24: ='DATA ROOM 1'!L20 -> 2883 | K24: ='DATA ROOM 1'!M20 -> 3390
B25: ='DATA ROOM 1'!B21 -> Plant Machinery | G25: ='DATA ROOM 1'!I21 -> 4208 | H25: ='DATA ROOM 1'!J21 -> 4340 | I25: ='DATA ROOM 1'!K21 -> 4531 | J25: ='DATA ROOM 1'!L21 -> 4825 | K25: ='DATA ROOM 1'!M21 -> 5422
B26: ='DATA ROOM 1'!B22 -> Equipments | G26: ='DATA ROOM 1'!I22 -> 241 | H26: ='DATA ROOM 1'!J22 -> 243 | I26: ='DATA ROOM 1'!K22 -> 253 | J26: ='DATA ROOM 1'!L22 -> 270 | K26: ='DATA ROOM 1'!M22 -> 298
B27: ='DATA ROOM 1'!B23 -> Furniture n fittings | G27: ='DATA ROOM 1'!I23 -> 94 | H27: ='DATA ROOM 1'!J23 -> 99 | I27: ='DATA ROOM 1'!K23 -> 113 | J27: ='DATA ROOM 1'!L23 -> 146 | K27: ='DATA ROOM 1'!M23 -> 175
B28: ='DATA ROOM 1'!B24 -> Vehicles | G28: ='DATA ROOM 1'!I24 -> 43 | H28: ='DATA ROOM 1'!J24 -> 38 | I28: ='DATA ROOM 1'!K24 -> 32 | J28: ='DATA ROOM 1'!L24 -> 36 | K28: ='DATA ROOM 1'!M24 -> 40
B29: ='DATA ROOM 1'!B25 -> Intangible Assets | G29: ='DATA ROOM 1'!I25 -> 505 | H29: ='DATA ROOM 1'!J25 -> 476 | I29: ='DATA ROOM 1'!K25 -> 345 | J29: ='DATA ROOM 1'!L25 -> 422 | K29: ='DATA ROOM 1'!M25 -> 850
B30: ='DATA ROOM 1'!B26 -> Other fixed assets | G30: ='DATA ROOM 1'!I26 -> 293 | H30: ='DATA ROOM 1'!J26 -> 302 | I30: ='DATA ROOM 1'!K26 -> 294 | J30: ='DATA ROOM 1'!L26 -> 289 | K30: ='DATA ROOM 1'!M26 -> 321
B31: Gross Block | G31: =SUM(G23:G30) -> 8281 | H31: =SUM(H23:H30) -> 8391 | I31: =SUM(I23:I30) -> 8537 | J31: =SUM(J23:J30) -> 9675 | K31: =SUM(K23:K30) -> 11622
B32: Accumulated Depriciation | G32: =-'DATA ROOM 1'!I28 -> -2010 | H32: =-'DATA ROOM 1'!J28 -> -2533 | I32: =-'DATA ROOM 1'!K28 -> -3019 | J32: =-'DATA ROOM 1'!L28 -> -3905 | K32: =-'DATA ROOM 1'!M28 -> -4475
A33: # | B33: Net Non Current Asset | G33: =SUM(G31:G32) -> 6271 | H33: =SUM(H31:H32) -> 5858 | I33: =SUM(I31:I32) -> 5518 | J33: =SUM(J31:J32) -> 5770 | K33: =SUM(K31:K32) -> 7147
A35: # | B35: Invested Capital | G35: =G33+G20 -> 13195 | H35: =H33+H20 -> 14825 | I35: =I33+I20 -> 18419 | J35: =J33+J20 -> 19654 | K35: =K33+K20 -> 21531
B36: EBIT | G36: 9904.09 | H36: 1073.7 | I36: -3438.36 | J36: 8740.72 | K36: -115.6
B38: ROIC | G38: =G36/G35 -> 0.75059416 | H38: =H36/H35 -> 0.072424958 | I38: =I36/I35 -> -0.18667463 | J38: =J36/J35 -> 0.44472983 | K38: =K36/K35 -> -0.0053690028
B41: Calculation Of Reinvested Rate | G41: =G3 -> 44256 | H41: =H3 -> 44621 | I41: =I3 -> 44986 | J41: =J3 -> 45352 | K41: =K3 -> 45717
B43: Net Capex | G43: =-SUM('DATA ROOM 1'!I53:I54) -> 377 | H43: =-SUM('DATA ROOM 1'!J53:J54) -> 261 | I43: =-SUM('DATA ROOM 1'!K53:K54) -> 511 | J43: =-SUM('DATA ROOM 1'!L53:L54) -> 1420 | K43: =-SUM('DATA ROOM 1'!M53:M54) -> 2491
B44: Change in Working Capital | H44: =H20-G20 -> 2043 | I44: =I20-H20 -> 3934 | J44: =J20-I20 -> 983 | K44: =K20-J20 -> 500
B46: EBIT | G46: =G36 -> 9904.09 | H46: =H36 -> 1073.7 | I46: =I36 -> -3438.36 | J46: =J36 -> 8740.72 | K46: =K36 -> -115.6
B47: Marginal Tax Rate | G47: 0.25 | H47: 0.25 | I47: 0.25 | J47: 0.25 | K47: 0.25
B48: EBIT(1-t) | G48: =G46*1-G47 -> 9903.84 | H48: =H46*1-H47 -> 1073.45 | I48: =I46*1-I47 -> -3438.61 | J48: =J46*1-J47 -> 8740.47 | K48: =K46*1-K47 -> -115.85
B50: Reinvestment | H50: =SUM(H46:H47) -> 1073.95 | I50: =SUM(I46:I47) -> -3438.11 | J50: =SUM(J46:J47) -> 8740.97 | K50: =SUM(K46:K47) -> -115.35
B52: Reinvestment Rate | H52: =H50/H48 -> 1.0004658 | I52: =I50/I48 -> 0.99985459 | J52: =J50/J48 -> 1.0000572 | K52: =K50/K48 -> 0.99568407
J54: 4 Year Average | K54: =AVERAGE(H52:K52) -> 0.99901541
J55: 4 Year Median | K55: =MEDIAN(H52:K52) -> 0.9999559
B57: Calculation of Growth Rate | G57: =G41 -> 44256 | H57: =H41 -> 44621 | I57: =I41 -> 44986 | J57: =J41 -> 45352 | K57: =K41 -> 45717
B59: Reinvestment Rate | H59: =H52 -> 1.0004658 | I59: =I52 -> 0.99985459 | J59: =J52 -> 1.0000572 | K59: =K52 -> 0.99568407
...

Sheet DCF
B2: Calculation Of PV FCFF | F2: ='INTRINSIC GROWTH '!K3 -> 45717 | G2: =F2+365 -> 46082 | H2: =G2+365 -> 46447 | I2: =H2+366 -> 46813 | J2: =I2+365 -> 47178 | K2: =J2+365 -> 47543
B4: EBIT | F4: ='INTRINSIC GROWTH '!K46 -> -115.6 | G4: =F4*(1+$C$14) -> -139.587 | H4: =G4*(1+$C$14) -> -168.5513 | I4: =H4*(1+$C$14) -> -203.5257 | J4: =I4*(1+$C$14) -> -245.75728 | K4: =J4*(1+$C$14) -> -296.75192
B5: Tax Rate | F5: ='INTRINSIC GROWTH '!G47 -> 0.25 | G5: ='INTRINSIC GROWTH '!H47 -> 0.25 | H5: ='INTRINSIC GROWTH '!I47 -> 0.25 | I5: ='INTRINSIC GROWTH '!J47 -> 0.25 | J5: ='INTRINSIC GROWTH '!K47 -> 0.25 | K5: 0.25
B6: EBIT(1-T) | F6: =F4*1-F5 -> -115.85 | G6: =G4*1-G5 -> -139.837 | H6: =H4*1-H5 -> -168.8013 | I6: =I4*1-I5 -> -203.7757 | J6: =J4*1-J5 -> -246.00728 | K6: =K4*1-K5 -> -297.00192
B7: Less: Reinvestment Rate | F7: ='INTRINSIC GROWTH '!K54 -> 0.99901541 | G7: =F7 -> 0.99901541 | H7: =G7 -> 0.99901541 | I7: =H7 -> 0.99901541 | J7: =I7 -> 0.99901541 | K7: 0.47
B8: Free Cash Flow Of Firm (FCFF) | F8: =F6*(1-F7) -> -0.11406418 | G8: =G6*(1-G7) -> -0.13768142 | H8: =H6*(1-H7) -> -0.16619924 | I8: =I6*(1-I7) -> -0.20063451 | J8: =J6*(1-J7) -> -0.2422151 | K8: =K6*(1-K7) -> -157.41102
B9: Mid Year Convention | G9: 0.5 | H9: =G9+1 -> 1.5 | I9: =H9+1 -> 2.5 | J9: =I9+1 -> 3.5 | K9: =J9+1 -> 4.5
B10: Discounting Factor | G10: =1/(1+$C$16)^G9 -> 0.96750537 | H10: =1/(1+$C$16)^H9 -> 0.90564951 | I10: =1/(1+$C$16)^I9 -> 0.8477483 | J10: =1/(1+$C$16)^J9 -> 0.79354891 | K10: =1/(1+$C$16)^K9 -> 0.74281467
B12: PV of FCFF | G12: =G8*G10 -> -0.13320752 | H12: =H8*H10 -> -0.15051826 | I12: =I8*I10 -> -0.17008757 | J12: =J8*J10 -> -0.19220953 | K12: =K8*K10 -> -116.92721
B14: Expected Growth | C14: 0.2075
B15: Terminal Growth | C15: 0.0538
B16: WACC | C16: 0.0683
B18: Calculation of Terminal value | G18: Calculation of Senstivity Analysis
G19: =C30 -> -2900.5524 | H19: 0.04 | I19: 0.0683 | J19: 0.08 | K19: 0.1
B20: FCFF (n+1) | C20: =K8*(1+C14) -> -190.0738 | G20: 0.03 | H20: -4869.4483 | I20: -2900.5286 | J20: -2493.5257 | K20: -2018.3412
B21: WACC | C21: =C16 -> 0.0683 | G21: 0.04 | H21: -4869.4583 | I21: -2900.5386 | J21: -2493.5357 | K21: -2018.3512
B22: Terminal Growth Rate | C22: =C15 -> 0.0538 | G22: 0.0538 | H22: -4869.4721 | I22: -2900.5524 | J22: -2493.5495 | K22: -2018.365
G23: 0.06 | H23: -4869.4783 | I23: -2900.5586 | J23: -2493.5557 | K23: -2018.3712
B24: Termonal value | C24: =C20/C21-C22 -> -2782.9791
B26: Calculation of Equity Value per share
B28: PV of FCFF | C28: =SUM(G12:K12) -> -117.57323
B29: PV OF Terminal value | C29: =C24 -> -2782.9791
B30: value of operating assets | C30: =SUM(DCF!C28:C29) -> -2900.5524
B32: add: cash | C32: 864.33
B33: less:debt | C33: =SUM('DATA ROOM 1'!M7:M8) -> 1107
B34: Value of Equity | C34: =C30+C32-C33 -> -3143.2224
B35: No. of Shares | C35: 95.92
B37: Equity value per share | C37: =C34/C35 -> -32.769207
